Workbook
Name _Hlk76029817: 'ZTE ER2020E (out)'!#REF!
Name RETE26: '(servizio)'!$J$2:$J$5
Name RETE27: '(servizio)'!$K$2:$K$8
Name RETE28: '(servizio)'!$L$2:$L$17
Name RETE29: '(servizio)'!$M$2:$M$33
Name RETE30: '(servizio)'!$N$2:$N$65
Name sottorete: '(servizio)'!$J$1:$N$1

Sheet Sheet1
A6: INDIRIZZAMENTO IP
A7: Per la configurazione iniziale deve essere fornita al costruttore e/o alla ditta installatrice, dalle funzioni territoriali competenti: una network /29 avente maschera 255.255.255.248 (di seguito denominata Network /29); una network /28 avente maschera 255.255.255.240 (di seguito denominata Network /28) per poter indirizzare i terminali. Gli indirizzi devono essere utilizzati secondo quanto indicato nella Tabelle di seguito.

Sheet ZTE NR9250 (out)
L1: le celle evidenziate in rosso indicano l'idirizzo IP di cui si deve richiedere il caricamento sui server TACACS+
E2: NETWORK | G2: Netmask
B4: Network vs. DACON | C4: 18 | D4: 21 | E4: 5 | F4: 240 | G4: 29
B6: Network Vs. radio | C6: 18 | D6: 21 | E6: 133 | F6: 240 | G6: 28
I10: 1a TRATTA RADIO | M10: 2a TRATTA RADIO | Q10: 3a TRATTA RADIO
B12: =CONCATENATE($C$4,".",$D$4,".",$E$4,".",$F$4,"/",$G$4) -> 18.21.5.240/29 | C12: +0 | D12: =F4 -> 240 | E12: Network
C13: +1 | D13: =D12+1 -> 241 | E13: Dacon GW | G13: router dacon
C14: +2 | D14: =D13+1 -> 242 | E14: Dacon (riservato)
C15: +3 | D15: =D14+1 -> 243 | E15: Dacon (riservato)
C16: +4 | D16: =D15+1 -> 244 | E16: Idu locale
C17: +5 | D17: =D16+1 -> 245 | E17: LIBERO
C18: +6 | D18: =D17+1 -> 246 | E18: LIBERO
C19: +7 | D19: =D18+1 -> 247 | E19: Broadcast
H20: SMART DCN SUBNET Y 18.21.133.240/28
B21: =CONCATENATE($C$6,".",$D$6,".",$E$6,".",$F$6,"/",$G$6) -> 18.21.133.240/28 | C21: +0 | D21: =F6 -> 240 | E21: Network/28 | H21: =CONCATENATE($C$6,".",$D$6,".",$E$6,".",$F$6+1) -> 18.21.133.241 | J21: =CONCATENATE($C$6,".",$D$6,".",$E$6,".",$F$6+2) -> 18.21.133.242 | L21: =CONCATENATE($C$6,".",$D$6,".",$E$6,".",$F$6+3) -> 18.21.133.243 | N21: =CONCATENATE($C$6,".",$D$6,".",$E$6,".",$F$6+4) -> 18.21.133.244 | P21: =CONCATENATE($C$6,".",$D$6,".",$E$6,".",$F$6+5) -> 18.21.133.245 | R21: =CONCATENATE($C$6,".",$D$6,".",$E$6,".",$F$6+6) -> 18.21.133.246
C22: +1 | D22: =F6+1 -> 241 | E22: Idu locale / 32 | H22: =VLOOKUP($G$6+4,'(servizio)'!$A$2:$B$25,2) -> 255.255.255.255 | J22: =VLOOKUP($G$6+4,'(servizio)'!$A$2:$B$25,2) -> 255.255.255.255 | L22: =VLOOKUP($G$6+4,'(servizio)'!$A$2:$B$25,2) -> 255.255.255.255 | N22: =VLOOKUP($G$6+4,'(servizio)'!$A$2:$B$25,2) -> 255.255.255.255 | P22: =VLOOKUP($G$6+4,'(servizio)'!$A$2:$B$25,2) -> 255.255.255.255 | R22: =VLOOKUP($G$6+4,'(servizio)'!$A$2:$B$25,2) -> 255.255.255.255
C23: +2 | D23: =F6+2 -> 242 | E23: Idu remota 1 /32
C24: +3 | D24: =F6+3 -> 243 | E24: Idu remota 2 /32
C25: +4 | D25: =F6+4 -> 244 | E25: Idu remota 3 /32 | G25: NETWORK | H25: =CONCATENATE($C$4,".",$D$4,".",$E$4,".",$F$4,"/",$G$4) -> 18.21.5.240/29
C26: +5 | D26: =F6+5 -> 245 | E26: Idu remota 4 /32 | G26: IP | H26: =CONCATENATE($C$4,".",$D$4,".",$E$4,".",$F$4+4) -> 18.21.5.244
C27: +6 | D27: =F6+6 -> 246 | E27: Idu remota 5 /32 | G27: NETMASK | H27: =VLOOKUP(G4,'(servizio)'!$A$2:$B$24,2) -> 255.255.255.248
C28: +7 | D28: =F6+7 -> 247 | E28: libero | G28: DEFAULT GATEWAY | H28: =CONCATENATE($C$4,".",$D$4,".",$E$4,".",$F$4+1,"/",$G$4) -> 18.21.5.241/29
C29: +8 | D29: =F6+8 -> 248 | E29: libero | G29: IP LOOPBACK (lo) - SMART DCN IP | H29: =CONCATENATE($C$6,".",$D$6,".",$E$6,".",$F$6+1) -> 18.21.133.241
C30: +9 | D30: =F6+9 -> 249 | E30: libero
C31: +10 | D31: =F6+10 -> 250 | E31: libero
C32: +11 | D32: =F6+11 -> 251 | E32: libero
C33: +12 | D33: =F6+12 -> 252 | E33: libero | H33: LMT PORT --> 192.168.1.1
C34: +13 | D34: =F6+13 -> 253 | E34: libero | H34: TAL | J34: TAL | L34: TAL | N34: TAL | P34: TAL | R34: TAL
C35: +14 | D35: =F6+14 -> 254 | E35: libero | H35: gei-1/2/0/1 | J35: gei-1/2/0/1 | L35: gei-1/2/0/1 | N35: gei-1/2/0/1 | P35: gei-1/2/0/1 | R35: gei-1/2/0/1
C36: +15 | D36: =F6+15 -> 255 | E36: Broadcast/28 | H36: 10.0.0.1 /30 | J36: 10.0.0.1 /30 | L36: 10.0.0.1 /30 | N36: 10.0.0.1 /30 | P36: 10.0.0.1 /30 | R36: 10.0.0.1 /30
H37: LAPTOP | J37: LAPTOP | L37: LAPTOP | N37: LAPTOP | P37: LAPTOP | R37: LAPTOP
H38: 10.0.0.2 /30 | J38: 10.0.0.2 /30 | L38: 10.0.0.2 /30 | N38: 10.0.0.2 /30 | P38: 10.0.0.2 /30 | R38: 10.0.0.2 /30
H39: 10.0.0.1 GW | J39: 10.0.0.1 GW | L39: 10.0.0.1 GW | N39: 10.0.0.1 GW | P39: 10.0.0.1 GW | R39: 10.0.0.1 GW
H46: ROTTE STATICHE
H47: Default Route | I47: NEXT HOP
H48: 0.0.0.0 0.0.0.0 | I48: 18.21.5.241

Sheet ZTE NR9250 (in)
L1: le celle evidenziate in rosso indicano l'idirizzo IP di cui si deve richiedere il caricamento sui server TACACS+
C2: NETWORK | G2: Netmask
B3: Network vs. DACON | C3: 18 | D3: 21 | E3: 5 | F3: 240 | G3: 29
B5: Network Vs. radio | C5: 18 | D5: 21 | E5: 133 | F5: 240 | G5: 28
H9: 1a TRATTA RADIO | L9: 2a TRATTA RADIO | P9: 3a TRATTA RADIO
B11: =CONCATENATE($C$3,".",$D$3,".",$E$3,".",$F$3,"/",$G$3) -> 18.21.5.240/29 | C11: +0 | D11: =F3 -> 240 | E11: Network/29
C12: +1 | D12: =D11+1 -> 241 | E12: Dacon GW | G12: FE/RF
C13: +2 | D13: =D12+1 -> 242 | E13: IP LOCALE
C14: +3 | D14: =D13+1 -> 243 | E14: Libero
C15: +4 | D15: =D14+1 -> 244 | E15: Libero
C16: +5 | D16: =D15+1 -> 245 | E16: Libero
C17: +6 | D17: =D16+1 -> 246 | E17: Libero
C18: +7 | D18: =D17+1 -> 247 | E18: Broadcast/29
H19: SMART DCN SUBNET Y 18.21.133.240/28
B20: =CONCATENATE($C$5,".",$D$5,".",$E$5,".",$F$5,"/",$G$5) -> 18.21.133.240/28 | C20: +0 | D20: =F5 -> 240 | E20: Network/28 | H20: =CONCATENATE($C$5,".",$D$5,".",$E$5,".",$F$5+1) -> 18.21.133.241 | J20: =CONCATENATE($C$5,".",$D$5,".",$E$5,".",$F$5+2) -> 18.21.133.242 | L20: =CONCATENATE($C$5,".",$D$5,".",$E$5,".",$F$5+3) -> 18.21.133.243 | N20: =CONCATENATE($C$5,".",$D$5,".",$E$5,".",$F$5+4) -> 18.21.133.244 | P20: =CONCATENATE($C$5,".",$D$5,".",$E$5,".",$F$5+5) -> 18.21.133.245 | R20: =CONCATENATE($C$5,".",$D$5,".",$E$5,".",$F$5+6) -> 18.21.133.246
C21: +1 | D21: =F5+1 -> 241 | E21: IP LOCALE /32 | H21: =VLOOKUP($G$5+4,'(servizio)'!$A$2:$B$25,2) -> 255.255.255.255 | J21: =VLOOKUP($G$5+4,'(servizio)'!$A$2:$B$25,2) -> 255.255.255.255 | L21: =VLOOKUP($G$5+4,'(servizio)'!$A$2:$B$25,2) -> 255.255.255.255 | N21: =VLOOKUP($G$5+4,'(servizio)'!$A$2:$B$25,2) -> 255.255.255.255 | P21: =VLOOKUP($G$5+4,'(servizio)'!$A$2:$B$25,2) -> 255.255.255.255 | R21: =VLOOKUP($G$5+4,'(servizio)'!$A$2:$B$25,2) -> 255.255.255.255
C22: +2 | D22: =F5+2 -> 242 | E22: IP REMOTO 1 /32
C23: +3 | D23: =F5+3 -> 243 | E23: IP REMOTO 2 /32
C24: +4 | D24: =F5+4 -> 244 | E24: IP REMOTO 3 /32 | G24: NETWORK | H24: =CONCATENATE($C$3,".",$D$3,".",$E$3,".",$F$3,"/",$G$3) -> 18.21.5.240/29
C25: +5 | D25: =F5+5 -> 245 | E25: IP REMOTO 4 /32 | G25: IP | H25: =CONCATENATE($C$3,".",$D$3,".",$E$3,".",$F$3+2) -> 18.21.5.242
C26: +6 | D26: =F5+6 -> 246 | E26: IP REMOTO 5/32 | G26: NETMASK | H26: =VLOOKUP($G$3,'(servizio)'!$A$2:$B$24,2) -> 255.255.255.248
C27: +7 | D27: =F5+7 -> 247 | E27: libero | G27: IP LOOPBACK -SMART DCN IP | H27: =CONCATENATE($C$5,".",$D$5,".",$E$5,".",$F$5+1) -> 18.21.133.241
C28: +8 | D28: =F5+8 -> 248 | E28: libero | G28: VLAN DCN | H28: 3556
C29: +9 | D29: =F5+9 -> 249 | E29: libero | G29: SUB INTERFACE | H29: =CONCATENATE("gei-1/4/0/1",".",H28) -> gei-1/4/0/1.3556
C30: +10 | D30: =F5+10 -> 250 | E30: libero
C31: +11 | D31: =F5+11 -> 251 | E31: libero
C32: +12 | D32: =F5+12 -> 252 | E32: libero | H32: LMT PORT --> 192.168.1.1
C33: +13 | D33: =F5+13 -> 253 | E33: libero | H33: TAL | J33: TAL | L33: TAL | N33: TAL | P33: TAL | R33: TAL
C34: +14 | D34: =F5+14 -> 254 | E34: libero | H34: gei-1/2/0/1 | J34: gei-1/2/0/1 | L34: gei-1/2/0/1 | N34: gei-1/2/0/1 | P34: gei-1/2/0/1 | R34: gei-1/2/0/1
C35: +15 | D35: =F5+15 -> 255 | E35: Broadcast/28 | H35: 10.0.0.1 /30 | J35: 10.0.0.1 /30 | L35: 10.0.0.1 /30 | N35: 10.0.0.1 /30 | P35: 10.0.0.1 /30 | R35: 10.0.0.1 /30
H36: LAPTOP | J36: LAPTOP | L36: LAPTOP | N36: LAPTOP | P36: LAPTOP | R36: LAPTOP
H37: 10.0.0.2 /30 | J37: 10.0.0.2 /30 | L37: 10.0.0.2 /30 | N37: 10.0.0.2 /30 | P37: 10.0.0.2 /30 | R37: 10.0.0.2 /30
H38: 10.0.0.1 GW | J38: 10.0.0.1 GW | L38: 10.0.0.1 GW | N38: 10.0.0.1 GW | P38: 10.0.0.1 GW | R38: 10.0.0.1 GW
G41: ROTTE STATICHE
G42: Default Route | H42: NEXT HOP
G43: 0.0.0.0 0.0.0.0 | H43: 18.21.5.241

Sheet ZTE MBL (out)
I1: le celle evidenziate in rosso indicano l'idirizzo IP di cui si deve richiedere il caricamento sui server TACACS+
B4: NETWORK | F4: netmask
A5: Network vs. DACON | B5: 7 | C5: 8 | D5: 0 | E5: 72 | F5: 29
A7: Network Vs. radio | B7: 7 | C7: 8 | D7: 0 | E7: 80 | F7: 28
A12: =CONCATENATE($B$5,".",$C$5,".",$D$5,".",$E$5,"/",$F$5) -> 7.8.0.72/29 | B12: +0 | C12: =E5 -> 72 | D12: Network/29
B13: +1 | C13: =C12+1 -> 73 | D13: GATEWAY
B14: +2 | C14: =C13+1 -> 74 | D14: RISERVATO DACON
B15: +3 | C15: =C14+1 -> 75 | D15: RISERVATO DACON
B16: +4 | C16: =C15+1 -> 76 | D16: NR9250 LOCALE (DCN) | H16: FE/RF
B17: +5 | C17: =C16+1 -> 77 | D17: LIBERO
B18: +6 | C18: =C17+1 -> 78 | D18: LIBERO
B19: +7 | C19: =C18+1 -> 79 | D19: BROADCAST
A21: =CONCATENATE($B$7,".",$C$7,".",$D$7,".",$E$7,"/",$F$7) -> 7.8.0.80/28 | B21: +0 | C21: =E$7+B21 -> 80 | D21: Network/28
B22: +1 | C22: =E$7+B22 -> 81 | D22: NR9250 LOCALE(Smart DCN)
B23: +2 | C23: =E$7+B23 -> 82 | D23: ER2020E-H LOCALE(Smart DCN) | H23: LOCALE | K23: REMOTO
B24: +3 | C24: =E$7+B24 -> 83 | D24: ER2020E-V LOCALE(Smart DCN) | H24: NETWORK | I24: =CONCATENATE($B$5,".",$C$5,".",$D$5,".",$E$5,"/",$F$5) -> 7.8.0.72/29 | K24: NETWORK | L24: =CONCATENATE($B$7,".",$C$7,".",$D$7,".",$E$7,"/",28) -> 7.8.0.80/28
B25: +4 | C25: =E$7+B25 -> 84 | D25: NR9250 REMOTA(Smart DCN) | H25: IP NR9250 | I25: =CONCATENATE($B$5,".",$C$5,".",$D$5,".",$E$5+4) -> 7.8.0.76 | K25: IP NR9250 - SMART DCN | L25: =CONCATENATE($B$7,".",$C$7,".",$D$7,".",$E$7+4) -> 7.8.0.84
B26: +5 | C26: =E$7+B26 -> 85 | D26: ER2020E-H REMOTA(Smart DCN) | H26: NETMASK | I26: =VLOOKUP($F$5,'[1](servizio)'!$A$2:$B$24,2) -> 255.255.255.248 | K26: NETMASK | L26: =VLOOKUP($F$7,'[1](servizio)'!$A$2:$B$25,2) -> 255.255.255.240
B27: +6 | C27: =E$7+B27 -> 86 | D27: ER2020E-V REMOTA(Smart DCN) | H27: IP ER2020E -H - SMART DCN | I27: =CONCATENATE($B$7,".",$C$7,".",$D$7,".",$E$7+2) -> 7.8.0.82 | K27: IP ER2020E-H - SMART DCN | L27: =CONCATENATE($B$7,".",$C$7,".",$D$7,".",$E$7+5) -> 7.8.0.85
B28: +7 | C28: =E$7+B28 -> 87 | D28: LIBERO | H28: IP ER2020E -V - SMART DCN | I28: =CONCATENATE($B$7,".",$C$7,".",$D$7,".",$E$7+3) -> 7.8.0.83 | K28: IP ER2020E-V - SMART DCN | L28: =CONCATENATE($B$7,".",$C$7,".",$D$7,".",$E$7+6) -> 7.8.0.86
B29: +8 | C29: =E$7+B29 -> 88 | D29: LIBERO | H29: NETMASK | I29: =VLOOKUP($F$7,'[1](servizio)'!$A$2:$B$25,2) -> 255.255.255.240 | K29: NETMASK | L29: =VLOOKUP($F$7,'[1](servizio)'!$A$2:$B$25,2) -> 255.255.255.240
B30: +9 | C30: =E$7+B30 -> 89 | D30: LIBERO
B31: +10 | C31: =E$7+B31 -> 90 | D31: LIBERO
B32: +11 | C32: =E$7+B32 -> 91 | D32: LIBERO | H32: ROTTE STATICHE
B33: +12 | C33: =E$7+B33 -> 92 | D33: LIBERO | H33: Default Route | I33: NEXT HOP
B34: +13 | C34: =E$7+B34 -> 93 | D34: LIBERO | H34: 0.0.0.0 0.0.0.0 | I34: =CONCATENATE($B$5,".",$C$5,".",$D$5,".",$E$5+1) -> 7.8.0.73
B35: +14 | C35: =E$7+B35 -> 94 | D35: LIBERO
B36: +15 | C36: =E$7+B36 -> 95 | D36: BROADCAST/28
I38: LMT PORT --> 192.168.1.1
I39: TAL-NR9250_1 | K39: TAL-NR9250_2
I40: gei-1/2/0/1 | K40: gei-1/2/0/1
I41: 10.0.0.1 /30 | K41: 10.0.0.1 /30
I42: LAPTOP | K42: LAPTOP
I43: 10.0.0.2 /30 | K43: 10.0.0.2 /30
I44: 10.0.0.1 GW | K44: 10.0.0.1 GW
I47: ER2020E-H LOCALE | K47: ER2020E-H REMOTO
I48: gei-1/1/0/1 | K48: gei-1/1/0/1
I49: 10.0.0.3 /28 | K49: 10.0.0.5 /28
I50: LAPTOP | K50: LAPTOP
I51: 10.0.0.2 /28 | K51: 10.0.0.2 /28
...

Sheet ZTE MBL (in)
I1: le celle evidenziate in rosso indicano l'idirizzo IP di cui si deve richiedere il caricamento sui server TACACS+
B4: NETWORK | F4: netmask
A5: Network vs. DACON | B5: 7 | C5: 8 | D5: 0 | E5: 72 | F5: 29
A7: Network Vs. radio | B7: 7 | C7: 8 | D7: 0 | E7: 80 | F7: 28
A12: =CONCATENATE($B$5,".",$C$5,".",$D$5,".",$E$5,"/",$F$5) -> 7.8.0.72/29 | B12: +0 | C12: =E5 -> 72 | D12: Network/29
B13: +1 | C13: =C12+1 -> 73 | D13: Dacon GW
B14: +2 | C14: =C13+1 -> 74 | D14: IP LOCALE NR9250 (su GE o XGE)
B15: +3 | C15: =C14+1 -> 75 | D15: Libero
B16: +4 | C16: =C15+1 -> 76 | D16: Libero | H16: FE/RF
B17: +5 | C17: =C16+1 -> 77 | D17: Libero
B18: +6 | C18: =C17+1 -> 78 | D18: Libero
B19: +7 | C19: =C18+1 -> 79 | D19: Broadcast/29
A21: =CONCATENATE($B$7,".",$C$7,".",$D$7,".",$E$7,"/",$F$7) -> 7.8.0.80/28 | B21: +0 | C21: =E$7+B21 -> 80 | D21: Network/28
B22: +1 | C22: =E$7+B22 -> 81 | D22: NR9250 LOCALE(Smart DCN)
B23: +2 | C23: =E$7+B23 -> 82 | D23: ER2020E-H LOCALE(Smart DCN) | H23: LOCALE | K23: REMOTO
B24: +3 | C24: =E$7+B24 -> 83 | D24: ER2020E-V LOCALE(Smart DCN) | H24: NETWORK | I24: =CONCATENATE($B$5,".",$C$5,".",$D$5,".",$E$5,"/",$F$5) -> 7.8.0.72/29 | K24: NETWORK | L24: =CONCATENATE($B$7,".",$C$7,".",$D$7,".",$E$7,"/",28) -> 7.8.0.80/28
B25: +4 | C25: =E$7+B25 -> 84 | D25: NR9250 REMOTA(Smart DCN) | H25: IP NR9250 | I25: =CONCATENATE($B$5,".",$C$5,".",$D$5,".",$E$5+2) -> 7.8.0.74 | K25: IP NR9250 - SMART DCN | L25: =CONCATENATE($B$7,".",$C$7,".",$D$7,".",$E$7+4) -> 7.8.0.84
B26: +5 | C26: =E$7+B26 -> 85 | D26: ER2020E-H REMOTA(Smart DCN) | H26: NETMASK | I26: =VLOOKUP($F$5,'[1](servizio)'!$A$2:$B$24,2) -> 255.255.255.248 | K26: NETMASK | L26: =VLOOKUP($F$7,'[1](servizio)'!$A$2:$B$25,2) -> 255.255.255.240
B27: +6 | C27: =E$7+B27 -> 86 | D27: ER2020E-V REMOTA(Smart DCN) | H27: VLAN DCN | I27: 3556 | K27: IP ER2020E-H - SMART DCN | L27: =CONCATENATE($B$7,".",$C$7,".",$D$7,".",$E$7+5) -> 7.8.0.85
B28: +7 | C28: =E$7+B28 -> 87 | D28: LIBERO | H28: SUB INTERFACE | I28: su gei0/1 o xgei0/3 | K28: IP ER2020E-V - SMART DCN | L28: =CONCATENATE($B$7,".",$C$7,".",$D$7,".",$E$7+6) -> 7.8.0.86
B29: +8 | C29: =E$7+B29 -> 88 | D29: LIBERO | H29: IP ER2020E -H - SMART DCN | I29: =CONCATENATE($B$7,".",$C$7,".",$D$7,".",$E$7+2) -> 7.8.0.82
B30: +9 | C30: =E$7+B30 -> 89 | D30: LIBERO | H30: IP ER2020E -V - SMART DCN | I30: =CONCATENATE($B$7,".",$C$7,".",$D$7,".",$E$7+3) -> 7.8.0.83
B31: +10 | C31: =E$7+B31 -> 90 | D31: LIBERO | H31: NETMASK | I31: =VLOOKUP($F$7,'[1](servizio)'!$A$2:$B$25,2) -> 255.255.255.240
B32: +11 | C32: =E$7+B32 -> 91 | D32: LIBERO
B33: +12 | C33: =E$7+B33 -> 92 | D33: LIBERO
B34: +13 | C34: =E$7+B34 -> 93 | D34: LIBERO | H34: ROTTE STATICHE
B35: +14 | C35: =E$7+B35 -> 94 | D35: LIBERO | H35: Default Route | I35: NEXT HOP
B36: +15 | C36: =E$7+B36 -> 95 | D36: BROADCAST/28 | H36: 0.0.0.0 0.0.0.0 | I36: =CONCATENATE($B$5,".",$C$5,".",$D$5,".",$E$5+1) -> 7.8.0.73
I40: LMT PORT --> 192.168.1.1
I41: TAL-NR9250_1 | K41: TAL-NR9250_2
I42: gei-1/2/0/1 | K42: gei-1/2/0/1
I43: 10.0.0.1 /30 | K43: 10.0.0.1 /30
I44: LAPTOP | K44: LAPTOP
I45: 10.0.0.2 /30 | K45: 10.0.0.2 /30
I46: 10.0.0.1 GW | K46: 10.0.0.1 GW
I48: ER2020E-H LOCALE | K48: ER2020E-H REMOTO
I49: gei-1/1/0/1 | K49: gei-1/1/0/1
I50: 10.0.0.3 /28 | K50: 10.0.0.5 /28
I51: LAPTOP | K51: LAPTOP
I52: 10.0.0.2 /28 | K52: 10.0.0.2 /28
...

Sheet ZTE ER2020E (out)
I1: le celle evidenziate in rosso indicano l'idirizzo IP di cui si deve richiedere il caricamento sui server TACACS+
E2: NETWORK | G2: Netmask
B4: Network vs. DACON -V | C4: 10 | D4: 10 | E4: 10 | F4: 0 | G4: 29
B6: Network Vs. Radio -V | C6: 20 | D6: 20 | E6: 20 | F6: 0 | G6: 28
B10: Network vs. DACON -H | C10: 30 | D10: 30 | E10: 30 | F10: 0 | G10: 29
B12: Network Vs. Radio -H | C12: 40 | D12: 40 | E12: 40 | F12: 0 | G12: 28
B14: ER2020 POL. V
B15: =CONCATENATE($C$4,".",$D$4,".",$E$4,".",$F$4,"/",$G$4) -> 10.10.10.0/29 | C15: +0 | D15: =F4 -> 0 | E15: Network | J15: =CONCATENATE("SMART DCN IP V _",$C$6,".",$D$6,".",$E$6,".",$F$6,"/",$G$6) -> SMART DCN IP V _20.20.20.0/28
C16: +1 | D16: =D15+1 -> 1 | E16: Dacon GW | G16: NETWORK | H16: =CONCATENATE($C$4,".",$D$4,".",$E$4,".",$F$4,"/",$G$4) -> 10.10.10.0/29 | J16: =CONCATENATE($C$6,".",$D$6,".",$E$6,".",$F$6+1) -> 20.20.20.1 | N16: =CONCATENATE($C$6,".",$D$6,".",$E$6,".",$F$6+2) -> 20.20.20.2
C17: +2 | D17: =D16+1 -> 2 | E17: Dacon (riservato) | G17: IP | H17: =CONCATENATE($C$4,".",$D$4,".",$E$4,".",$F$4+4) -> 10.10.10.4 | J17: =VLOOKUP($G$6+4,'[1](servizio) (2)'!$A$2:$B$25,2) -> 255.255.255.255 | N17: =VLOOKUP($G$6+4,'[1](servizio) (2)'!$A$2:$B$25,2) -> 255.255.255.255
C18: +3 | D18: =D17+1 -> 3 | E18: Dacon (riservato) | G18: NETMASK | H18: =VLOOKUP(G4,'[1](servizio) (2)'!$A$2:$B$24,2) -> 255.255.255.248
C19: +4 | D19: =D18+1 -> 4 | E19: ER2020E locale H | G19: DEFAULT GATEWAY | H19: =CONCATENATE($C$4,".",$D$4,".",$E$4,".",$F$4+1,"/",$G$4) -> 10.10.10.1/29
C20: +5 | D20: =D19+1 -> 5 | E20: LIBERO | G20: IP LOOPBACK (lo) - SMART DCN IP | H20: =CONCATENATE($C$6,".",$D$6,".",$E$6,".",$F$6+1) -> 20.20.20.1
C21: +6 | D21: =D20+1 -> 6 | E21: LIBERO
C22: +7 | D22: =D21+1 -> 7 | E22: Broadcast
B24: =CONCATENATE($C$6,".",$D$6,".",$E$6,".",$F$6,"/",$G$6) -> 20.20.20.0/28 | C24: +0 | D24: =F6 -> 0 | E24: Network/28
C25: +1 | D25: =F6+1 -> 1 | E25: ER2020E locale H /32
C26: +2 | D26: =F6+2 -> 2 | E26: ER2020E remota H /32
C27: +3 | D27: =F6+3 -> 3 | E27: libero
C28: +4 | D28: =F6+4 -> 4 | E28: libero
C29: +5 | D29: =F6+5 -> 5 | E29: libero
C30: +6 | D30: =F6+6 -> 6 | E30: libero
C31: +7 | D31: =F6+7 -> 7 | E31: libero
C32: +8 | D32: =F6+8 -> 8 | E32: libero
C33: +9 | D33: =F6+9 -> 9 | E33: libero
C34: +10 | D34: =F6+10 -> 10 | E34: libero
C35: +11 | D35: =F6+11 -> 11 | E35: libero
C36: +12 | D36: =F6+12 -> 12 | E36: libero
C37: +13 | D37: =F6+13 -> 13 | E37: libero
C38: +14 | D38: =F6+14 -> 14 | E38: libero
C39: +15 | D39: =F6+15 -> 15 | E39: Broadcast/28
B46: ER2020 POL. V
B47: =CONCATENATE($C$10,".",$D$10,".",$E$10,".",$F$10,"/",$G$10) -> 30.30.30.0/29 | C47: +0 | D47: =F43 -> 0 | E47: Network
C48: +1 | D48: =D47+1 -> 1 | E48: Dacon GW | G48: NETWORK | H48: =CONCATENATE($C$10,".",$D$10,".",$E$10,".",$F$10,"/",$G$10) -> 30.30.30.0/29 | J48: =CONCATENATE("SMART DCN IP V _",$C$12,".",$D$12,".",$E$12,".",$F$12,"/",$G$12) -> SMART DCN IP V _40.40.40.0/28
C49: +2 | D49: =D48+1 -> 2 | E49: Dacon (riservato) | G49: IP | H49: =CONCATENATE($C$10,".",$D$10,".",$E$10,".",$F$10+4) -> 30.30.30.4 | J49: =CONCATENATE($C$12,".",$D$12,".",$E$12,".",$F$12+1) -> 40.40.40.1 | N49: =CONCATENATE($C$12,".",$D$12,".",$E$12,".",$F$12+2) -> 40.40.40.2
C50: +3 | D50: =D49+1 -> 3 | E50: Dacon (riservato) | G50: NETMASK | H50: =VLOOKUP(G4,'[1](servizio) (2)'!$A$2:$B$24,2) -> 255.255.255.248 | J50: =VLOOKUP($G$6+4,'[1](servizio) (2)'!$A$2:$B$25,2) -> 255.255.255.255 | N50: =VLOOKUP($G$6+4,'[1](servizio) (2)'!$A$2:$B$25,2) -> 255.255.255.255
C51: +4 | D51: =D50+1 -> 4 | E51: ER2020E locale V | G51: DEFAULT GATEWAY | H51: =CONCATENATE($C$10,".",$D$10,".",$E$10,".",$F$10+1,"/",$G$10) -> 30.30.30.1/29
C52: +5 | D52: =D51+1 -> 5 | E52: LIBERO | G52: IP LOOPBACK (lo) - SMART DCN IP | H52: =CONCATENATE($C$12,".",$D$12,".",$E$12,".",$F$12+1) -> 40.40.40.1
C53: +6 | D53: =D52+1 -> 6 | E53: LIBERO
C54: +7 | D54: =D53+1 -> 7 | E54: Broadcast
...

Sheet ZTE ER2020E (in)
I1: le celle evidenziate in rosso indicano l'idirizzo IP di cui si deve richiedere il caricamento sui server TACACS+
C2: NETWORK | G2: Netmask
B3: Network vs. DACON | C3: 10 | D3: 10 | E3: 10 | F3: 0 | G3: 29
B5: Network Vs. radio | C5: 20 | D5: 20 | E5: 20 | F5: 0 | G5: 28
H8: =CONCATENATE("SMART DCN SUBNET Y ",$C$5,".",$D$5,".",$E$5,".",$F$5,"/",$G$5) -> SMART DCN SUBNET Y 20.20.20.0/28
H9: =CONCATENATE($C$5,".",$D$5,".",$E$5,".",$F$5+1) -> 20.20.20.1 | K9: =CONCATENATE($C$5,".",$D$5,".",$E$5,".",$F$5+3) -> 20.20.20.3
H10: =VLOOKUP($G$5+4,'[1](servizio) (2)'!$A$2:$B$25,2) -> 255.255.255.255 | K10: =VLOOKUP($G$5+4,'[1](servizio) (2)'!$A$2:$B$25,2) -> 255.255.255.255
B14: =CONCATENATE($C$3,".",$D$3,".",$E$3,".",$F$3,"/",$G$3) -> 10.10.10.0/29 | C14: +0 | D14: =F3 -> 0 | E14: Network/29
C15: +1 | D15: =D14+1 -> 1 | E15: Dacon GW
C16: +2 | D16: =D15+1 -> 2 | E16: IP LOCALE H/V
C17: +3 | D17: =D16+1 -> 3 | E17: Libero
C18: +4 | D18: =D17+1 -> 4 | E18: Libero
C19: +5 | D19: =D18+1 -> 5 | E19: Libero
C20: +6 | D20: =D19+1 -> 6 | E20: Libero
C21: +7 | D21: =D20+1 -> 7 | E21: Broadcast/29
B23: =CONCATENATE($C$5,".",$D$5,".",$E$5,".",$F$5,"/",$G$5) -> 20.20.20.0/28 | C23: +0 | D23: =F5 -> 0 | E23: Network/28
C24: +1 | D24: =F5+1 -> 1 | E24: IP LOCALE H /32
C25: +2 | D25: =F5+2 -> 2 | E25: IP LOCALE V /32
C26: +3 | D26: =F5+3 -> 3 | E26: IP REMOTO H /32
C27: +4 | D27: =F5+4 -> 4 | E27: IP REMOTO V /32
C28: +5 | D28: =F5+5 -> 5 | E28: libero
C29: +6 | D29: =F5+6 -> 6 | E29: libero
C30: +7 | D30: =F5+7 -> 7 | E30: libero | H30: =CONCATENATE("SMART DCN SUBNET Y ",$C$5,".",$D$5,".",$E$5,".",$F$5,"/",$G$5) -> SMART DCN SUBNET Y 20.20.20.0/28
C31: +8 | D31: =F5+8 -> 8 | E31: libero | H31: =CONCATENATE($C$5,".",$D$5,".",$E$5,".",$F$5+2) -> 20.20.20.2 | K31: =CONCATENATE($C$5,".",$D$5,".",$E$5,".",$F$5+4) -> 20.20.20.4
C32: +9 | D32: =F5+9 -> 9 | E32: libero | H32: =VLOOKUP($G$5+4,'[1](servizio) (2)'!$A$2:$B$25,2) -> 255.255.255.255 | K32: =VLOOKUP($G$5+4,'[1](servizio) (2)'!$A$2:$B$25,2) -> 255.255.255.255
C33: +10 | D33: =F5+10 -> 10 | E33: libero
C34: +11 | D34: =F5+11 -> 11 | E34: libero
C35: +12 | D35: =F5+12 -> 12 | E35: libero
C36: +13 | D36: =F5+13 -> 13 | E36: libero | G36: NETWORK | H36: =CONCATENATE($C$3,".",$D$3,".",$E$3,".",$F$3,"/",$G$3) -> 10.10.10.0/29
C37: +14 | D37: =F5+14 -> 14 | E37: libero | G37: IP INTERFACE LOCALE H | H37: =CONCATENATE($C$3,".",$D$3,".",$E$3,".",$F$3+2) -> 10.10.10.2
C38: +15 | D38: =F5+15 -> 15 | E38: Broadcast/28 | G38: IP INTERFACE LOCALE V | H38: =CONCATENATE($C$3,".",$D$3,".",$E$3,".",$F$3+2) -> 10.10.10.2 | L38: ROTTE STATICHE
G39: NETMASK | H39: =VLOOKUP($G$3,'[1](servizio) (2)'!$A$2:$B$24,2) -> 255.255.255.248 | L39: Default Route | M39: NEXT HOP
G40: IP SMART DCN IP LOCALE H | H40: =CONCATENATE($C$5,".",$D$5,".",$E$5,".",$F$5+1) -> 20.20.20.1 | L40: 0.0.0.0 0.0.0.0 | M40: =CONCATENATE($C$3,".",$D$3,".",$E$3,".",$F$3+1) -> 10.10.10.1
G41: IP SMART DCN IP LOCALE V | H41: =CONCATENATE($C$5,".",$D$5,".",$E$5,".",$F$5+2) -> 20.20.20.2
G42: NETMASK | H42: =VLOOKUP($G$3,'[1](servizio) (2)'!$A$2:$B$22,2) -> 255.255.255.240
G43: VLAN DCN | H43: 3556
G44: SUB INTERFACE | H44: =CONCATENATE("xgei-1/1/0/3",".",H43) -> xgei-1/1/0/3.3556
I50: ER2020E-H LOCALE | K50: ER2020E-H REMOTO
I51: gei-1/1/0/1 | K51: gei-1/1/0/1
I52: 10.0.0.3 /28 | K52: 10.0.0.5 /28
...

Sheet (servizio)
A1: classi IP | B1: Netmask | F1: Rete huawei default | J1: 26 | K1: 27 | L1: 28 | M1: 29 | N1: 30
A2: 8 | B2: 255.0.0.0 | F2: 129.9.0 | G2: 0 | H2: 16 | J2: 0 | K2: 0 | L2: 0 | M2: 0 | N2: 0
A3: 9 | B3: 255.128.0.0 | J3: =J2+64 -> 64 | K3: =K2+32 -> 32 | L3: =L2+16 -> 16 | M3: =M2+8 -> 8 | N3: =N2+4 -> 4
A4: 10 | B4: 255.192.0.0 | J4: =J3+64 -> 128 | K4: =K3+32 -> 64 | L4: =L3+16 -> 32 | M4: =M3+8 -> 16 | N4: =N3+4 -> 8
A5: 11 | B5: 255.224.0.0 | J5: =J4+64 -> 192 | K5: =K4+32 -> 96 | L5: =L4+16 -> 48 | M5: =M4+8 -> 24 | N5: =N4+4 -> 12
A6: 12 | B6: 255.240.0.0 | K6: =K5+32 -> 128 | L6: =L5+16 -> 64 | M6: =M5+8 -> 32 | N6: =N5+4 -> 16
A7: 13 | B7: 255.248.0.0 | K7: =K6+32 -> 160 | L7: =L6+16 -> 80 | M7: =M6+8 -> 40 | N7: =N6+4 -> 20
A8: 14 | B8: 255.252.0.0 | K8: =K7+32 -> 192 | L8: =L7+16 -> 96 | M8: =M7+8 -> 48 | N8: =N7+4 -> 24
A9: 15 | B9: 255.254.0.0 | K9: =K8+32 -> 224 | L9: =L8+16 -> 112 | M9: =M8+8 -> 56 | N9: =N8+4 -> 28
A10: 16 | B10: 255.255.0.0 | L10: =L9+16 -> 128 | M10: =M9+8 -> 64 | N10: =N9+4 -> 32
A11: 17 | B11: 255.255.128.0 | L11: =L10+16 -> 144 | M11: =M10+8 -> 72 | N11: =N10+4 -> 36
A12: 18 | B12: 255.255.192.0 | L12: =L11+16 -> 160 | M12: =M11+8 -> 80 | N12: =N11+4 -> 40
A13: 19 | B13: 255.255.224.0 | L13: =L12+16 -> 176 | M13: =M12+8 -> 88 | N13: =N12+4 -> 44
A14: 20 | B14: 255.255.240.0 | L14: =L13+16 -> 192 | M14: =M13+8 -> 96 | N14: =N13+4 -> 48
A15: 21 | B15: 255.255.248.0 | L15: =L14+16 -> 208 | M15: =M14+8 -> 104 | N15: =N14+4 -> 52
A16: 22 | B16: 255.255.252.0 | L16: =L15+16 -> 224 | M16: =M15+8 -> 112 | N16: =N15+4 -> 56
A17: 23 | B17: 255.255.254.0 | L17: =L16+16 -> 240 | M17: =M16+8 -> 120 | N17: =N16+4 -> 60
A18: 24 | B18: 255.255.255.0 | M18: =M17+8 -> 128 | N18: =N17+4 -> 64
A19: 25 | B19: 255.255.255.128 | M19: =M18+8 -> 136 | N19: =N18+4 -> 68
A20: 26 | B20: 255.255.255.192 | M20: =M19+8 -> 144 | N20: =N19+4 -> 72
A21: 27 | B21: 255.255.255.224 | M21: =M20+8 -> 152 | N21: =N20+4 -> 76
A22: 28 | B22: 255.255.255.240 | M22: =M21+8 -> 160 | N22: =N21+4 -> 80
A23: 29 | B23: 255.255.255.248 | M23: =M22+8 -> 168 | N23: =N22+4 -> 84
A24: 30 | B24: 255.255.255.252 | M24: =M23+8 -> 176 | N24: =N23+4 -> 88
A25: 32 | B25: 255.255.255.255 | M25: =M24+8 -> 184 | N25: =N24+4 -> 92
M26: =M25+8 -> 192 | N26: =N25+4 -> 96
D27: Eri | E27: FI | F27: 180.2.25.0/25 | M27: =M26+8 -> 200 | N27: =N26+4 -> 100
D28: Eri | E28: PA1 | F28: 50.2.157.8/29 | M28: =M27+8 -> 208 | N28: =N27+4 -> 104
D29: Eri | E29: PA2 | F29: 50.2.157.16/29 | M29: =M28+8 -> 216 | N29: =N28+4 -> 108
M30: =M29+8 -> 224 | N30: =N29+4 -> 112
M31: =M30+8 -> 232 | N31: =N30+4 -> 116
B32: subnet: 160.2.151.0/29 | D32: Nokia NFM-P | E32: Pomezia | F32: 160.2.151.4/29 | M32: =M31+8 -> 240 | N32: =N31+4 -> 120
D33: TACACS+ | F33: 192.168.200.65/32 | M33: =M32+8 -> 248 | N33: =N32+4 -> 124
D34: TACACS+ | F34: 192.168.200.120/32 | N34: =N33+4 -> 128
N35: =N34+4 -> 132
N36: =N35+4 -> 136
N37: =N36+4 -> 140
N38: =N37+4 -> 144
N39: =N38+4 -> 148
N40: =N39+4 -> 152
...
